Workbook

Sheet Nasıl kullanılır
A1: Hangisi Daha Pahalı? — Başlangıç veri seti (Ekim 2026)
A3: Ürünler sekmesi: Mavi fiyatlar elle girilen değerlerdir; her birinin tarihi ve kaynak linki yanında. Türetilmiş satırlar (D..) formülle hesaplanır, kaynak fiyat değişince kendiliğinden güncellenir.
A4: Eşleşmeler sekmesi: Sarı hücrelere iki ürün ID'si yaz; isim, fiyat, kazanan ve fark % otomatik gelir. Fark % düşük olan eşleşmeler en zor ve en eğlenceli turlardır.
A5: Güncelleme: 'Güncelleme sıklığı' kolonu neyin ne kadar sık eskidiğini gösterir. Altın ve döviz her gün değişir; yayında kullanmadan önce mutlaka yenile ya da API'ye bağla (TCMB EVDS).
A6: Teyit gerekenler: iPhone 17 ve AirPods Pro 3 fiyatları Mayıs 2026 zammından; iPhone 18 lansmanı sonrası değişmiş olabilir. Ekmek fiyatı fırından fırına değişir.
A7: Kira: İlçe ortalamaları Endeksa'nın 100 m² standart konut verisidir (Eylül 2026 raporu); tek bir ilanı temsil etmez.
A8: Yeni ürün eklerken: ID'yi benzersiz ver (kategori harfi + numara), fiyatı mavi, tarihi ve kaynağı mutlaka doldur.

Sheet Ürünler
A1: ID | B1: Ürün | C1: Kategori | D1: Fiyat (TL) | E1: Not | F1: Fiyat tarihi | G1: Güncelleme sıklığı | H1: Kaynak
A2: G01 | B2: Simit (İstanbul) | C2: Gıda | D2: 30 | E2: Tezgâh fiyatı | F2: 26.09.2026 | G2: Aylık | H2: https://www.politikam.com/istanbulda-simide-zam-geldi-26-eylul-2026-simit-fiyati-kac-tl-oldu
A3: G02 | B3: Fırın ekmeği 200 g (İstanbul) | C3: Gıda | D3: 17.5 | E3: Fırına göre değişebilir | F3: 01.04.2026 | G3: Aylık | H3: https://www.haberturk.com/turkiye-firincilar-federasyonu-duyurdu-ekmege-zam-geldi-istanbul-da-ekmek-fiyatlari-ne-kadar-zam-geldi-mi-3873980
A4: G03 | B4: Halk Ekmek 250 g | C4: Gıda | D4: 12.5 | E4: İBB Halk Ekmek büfesi | F4: Ekim 2026 | G4: Aylık | H4: https://www.kayserianadoluhaber.com.tr/istanbul-da-kayseri-konya-ve-gaziantep-ornegi-halk-ekmek-te-istanbul-geride-mi-kaldi/200259
A5: U01 | B5: İstanbulkart tam biniş | C5: Ulaşım | D5: 46.2 | E5: Elektronik tam bilet | F5: 20.07.2026 | G5: Zam olunca | H5: https://www.gzt.com/ekonomi/istanbul-toplu-tasima-zammi-2026-son-dakika-marmaray-metro-otobus-ve-metrobus-ucreti-ne-kadar-oldu-iett-yeni-ucret-tarifesi-istanbul-ulasim-zammi-ne-zaman-uygulanacak-4242283
A6: U02 | B6: İstanbulkart öğrenci biniş | C6: Ulaşım | D6: 22.55 | F6: 20.07.2026 | G6: Zam olunca | H6: https://www.gzt.com/ekonomi/istanbul-toplu-tasima-zammi-2026-son-dakika-marmaray-metro-otobus-ve-metrobus-ucreti-ne-kadar-oldu-iett-yeni-ucret-tarifesi-istanbul-ulasim-zammi-ne-zaman-uygulanacak-4242283
A7: U03 | B7: Mavi Kart (aylık tam abonman) | C7: Ulaşım | D7: 3628 | F7: 20.07.2026 | G7: Zam olunca | H7: https://www.gzt.com/ekonomi/istanbul-toplu-tasima-zammi-2026-son-dakika-marmaray-metro-otobus-ve-metrobus-ucreti-ne-kadar-oldu-iett-yeni-ucret-tarifesi-istanbul-ulasim-zammi-ne-zaman-uygulanacak-4242283
A8: U04 | B8: Taksi açılış ücreti (İstanbul) | C8: Ulaşım | D8: 71.94 | F8: 20.07.2026 | G8: Zam olunca | H8: https://www.gzt.com/ekonomi/istanbul-toplu-tasima-zammi-2026-son-dakika-marmaray-metro-otobus-ve-metrobus-ucreti-ne-kadar-oldu-iett-yeni-ucret-tarifesi-istanbul-ulasim-zammi-ne-zaman-uygulanacak-4242283
A9: U05 | B9: Taksi kısa mesafe ücreti (İstanbul) | C9: Ulaşım | D9: 230 | F9: 20.07.2026 | G9: Zam olunca | H9: https://www.gzt.com/ekonomi/istanbul-toplu-tasima-zammi-2026-son-dakika-marmaray-metro-otobus-ve-metrobus-ucreti-ne-kadar-oldu-iett-yeni-ucret-tarifesi-istanbul-ulasim-zammi-ne-zaman-uygulanacak-4242283
A10: U06 | B10: YHT İstanbul–Ankara (tek yön, ekonomi) | C10: Ulaşım | D10: 990 | F10: 17.08.2026 | G10: Zam olunca | H10: https://www.bloomberght.com/yht-bilet-fiyatlarina-zam-yapildi-3785720
A11: U07 | B11: YHT İstanbul–Konya (tek yön, ekonomi) | C11: Ulaşım | D11: 1442 | F11: 17.08.2026 | G11: Zam olunca | H11: https://www.bloomberght.com/yht-bilet-fiyatlarina-zam-yapildi-3785720
A12: Y01 | B12: 1 litre benzin (İstanbul Avrupa) | C12: Akaryakıt | D12: 83.8 | F12: 15.10.2026 | G12: Haftalık | H12: https://www.yeniasir.com.tr/ekonomi/2026/10/15/depoyu-doldurmadan-once-bakin-15-ekim-benzin-motorin-ve-lpg-fiyatlari-akaryakita-zam-geldi-mi
A13: Y02 | B13: 1 litre motorin (İstanbul Avrupa) | C13: Akaryakıt | D13: 96.6 | F13: 15.10.2026 | G13: Haftalık | H13: https://www.yeniasir.com.tr/ekonomi/2026/10/15/depoyu-doldurmadan-once-bakin-15-ekim-benzin-motorin-ve-lpg-fiyatlari-akaryakita-zam-geldi-mi
A14: Y03 | B14: 1 litre LPG (İstanbul Avrupa) | C14: Akaryakıt | D14: 41.2 | F14: 15.10.2026 | G14: Haftalık | H14: https://www.yeniasir.com.tr/ekonomi/2026/10/15/depoyu-doldurmadan-once-bakin-15-ekim-benzin-motorin-ve-lpg-fiyatlari-akaryakita-zam-geldi-mi
A15: T01 | B15: iPhone 18 Pro 256 GB | C15: Teknoloji | D15: 137999 | E15: Apple Türkiye liste fiyatı | F15: Eylül 2026 | G15: Aylık | H15: https://www.tamindir.com/haber/yeni-iphone-modelleri-turkiye-fiyati_112035/
A16: T02 | B16: iPhone 18 Pro Max 256 GB | C16: Teknoloji | D16: 149999 | E16: Apple Türkiye liste fiyatı | F16: Eylül 2026 | G16: Aylık | H16: https://www.tamindir.com/haber/yeni-iphone-modelleri-turkiye-fiyati_112035/
A17: T03 | B17: iPhone 18 Pro Max 2 TB | C17: Teknoloji | D17: 255999 | E17: Apple Türkiye liste fiyatı | F17: Eylül 2026 | G17: Aylık | H17: https://www.tamindir.com/haber/yeni-iphone-modelleri-turkiye-fiyati_112035/
A18: T04 | B18: iPhone Duo 256 GB (katlanabilir) | C18: Teknoloji | D18: 229999 | E18: Apple Türkiye liste fiyatı | F18: Eylül 2026 | G18: Aylık | H18: https://www.tamindir.com/haber/yeni-iphone-modelleri-turkiye-fiyati_112035/
A19: T05 | B19: iPhone 17 256 GB | C19: Teknoloji | D19: 84999 | E19: Mayıs zammı sonrası; Apple sitesinden teyit et | F19: 05.05.2026 | G19: Aylık | H19: https://www.log.com.tr/apple-turkiye-iphone-17-ailesinin-fiyatlarina-zam-yapti/
A20: T06 | B20: AirPods Pro 3 | C20: Teknoloji | D20: 15499 | E20: Mayıs zammı sonrası; teyit et | F20: 05.05.2026 | G20: Aylık | H20: https://www.log.com.tr/apple-turkiye-iphone-17-ailesinin-fiyatlarina-zam-yapti/
A21: T07 | B21: PS5 Digital | C21: Teknoloji | D21: 57999 | E21: Amazon.com.tr teklifi | F21: 19.10.2026 | G21: Aylık | H21: https://www.teknoblog.com/oyun-konsolu-satin-alma-rehberi-2026
A22: T08 | B22: PS5 diskli + 2 DualSense | C22: Teknoloji | D22: 66999 | E22: Amazon.com.tr teklifi | F22: 19.10.2026 | G22: Aylık | H22: https://www.teknoblog.com/oyun-konsolu-satin-alma-rehberi-2026
A23: A01 | B23: Netflix Temel (aylık) | C23: Abonelik | D23: 259.99 | F23: Ekim 2026 | G23: Zam olunca | H23: https://teknoblog.com/netflix-turkiye-fiyatlari-ekim-2026
A24: A02 | B24: Netflix Standart (aylık) | C24: Abonelik | D24: 389.99 | F24: Ekim 2026 | G24: Zam olunca | H24: https://teknoblog.com/netflix-turkiye-fiyatlari-ekim-2026
A25: A03 | B25: Netflix Premium (aylık) | C25: Abonelik | D25: 499.99 | F25: Ekim 2026 | G25: Zam olunca | H25: https://teknoblog.com/netflix-turkiye-fiyatlari-ekim-2026
A26: A04 | B26: Spotify Premium Bireysel (aylık) | C26: Abonelik | D26: 115 | F26: 01.10.2026 | G26: Zam olunca | H26: https://www.dunya.com/sektorler/bilim-ve-teknoloji/spotify-aboneliklerine-zam-geldi-haberi-842318
A27: A05 | B27: Spotify Premium Öğrenci (aylık) | C27: Abonelik | D27: 60 | F27: 01.10.2026 | G27: Zam olunca | H27: https://www.dunya.com/sektorler/bilim-ve-teknoloji/spotify-aboneliklerine-zam-geldi-haberi-842318
A28: A06 | B28: Spotify Premium Aile (aylık) | C28: Abonelik | D28: 199 | F28: 01.10.2026 | G28: Zam olunca | H28: https://www.dunya.com/sektorler/bilim-ve-teknoloji/spotify-aboneliklerine-zam-geldi-haberi-842318
A29: O01 | B29: Togg T10X V1 RWD Standart Menzil | C29: Otomobil | D29: 1909048 | E29: Anahtar teslim liste | F29: Ekim 2026 | G29: Aylık | H29: https://www.milligazete.com.tr/togg-t10f-ve-t10x-ekim-fiyatlari-ne-kadar-2026-togg-guncel-fiyat-listesi
A30: O02 | B30: Togg T10F (giriş) | C30: Otomobil | D30: 1884980 | E30: Anahtar teslim liste | F30: Ekim 2026 | G30: Aylık | H30: https://www.milligazete.com.tr/togg-t10f-ve-t10x-ekim-fiyatlari-ne-kadar-2026-togg-guncel-fiyat-listesi
A31: O03 | B31: Renault Clio evolution plus | C31: Otomobil | D31: 1830000 | E31: Liste fiyatı | F31: 12.10.2026 | G31: Aylık | H31: https://www.teknoblog.com/renault-ekim-2026-fiyatlari/
A32: O04 | B32: Renault Duster (giriş) | C32: Otomobil | D32: 1865000 | E32: Liste fiyatı | F32: 12.10.2026 | G32: Aylık | H32: https://www.teknoblog.com/renault-ekim-2026-fiyatlari/
A33: O05 | B33: Renault 5 E-Tech Techno | C33: Otomobil | D33: 2140000 | E33: Liste fiyatı | F33: 12.10.2026 | G33: Aylık | H33: https://www.teknoblog.com/renault-ekim-2026-fiyatlari/
A34: O06 | B34: Fiat Egea Cross (giriş, kampanyalı) | C34: Otomobil | D34: 1890900 | E34: Nakit kampanyalı | F34: Ekim 2026 | G34: Aylık | H34: https://www.cnbce.com/otomotiv/fiat-ekim-ayi-fiyat-listesini-acikladi-en-cok-satan-modelde-kampanya-egea-fiyat-listesi-egea-cross-fiyat-listesi-fiat-ekim-fiyat-listesi-h38644
A35: O07 | B35: Fiat Grande Panda (kampanyalı) | C35: Otomobil | D35: 1584900 | E35: Nakit kampanyalı | F35: Ekim 2026 | G35: Aylık | H35: https://www.cnbce.com/otomotiv/fiat-ekim-ayi-fiyat-listesini-acikladi-en-cok-satan-modelde-kampanya-egea-fiyat-listesi-egea-cross-fiyat-listesi-fiat-ekim-fiyat-listesi-h38644
A36: O08 | B36: Fiat 500e Giorgio Armani | C36: Otomobil | D36: 2379900 | E36: Liste fiyatı | F36: Ekim 2026 | G36: Aylık | H36: https://www.cnbce.com/otomotiv/fiat-ekim-ayi-fiyat-listesini-acikladi-en-cok-satan-modelde-kampanya-egea-fiyat-listesi-egea-cross-fiyat-listesi-fiat-ekim-fiyat-listesi-h38644
A37: K01 | B37: Kadıköy 100 m² aylık kira | C37: Konut | D37: 65100 | E37: Endeksa ortalaması | F37: Eylül 2026 | G37: Aylık | H37: https://www.gazetebirlik.com/ekonomi/istanbulda-ortalama-kira-57-bin-100-tl-oldu-en-pahali-ve-en-ucuz-ilceler-belli-oldu/1091377
A38: K02 | B38: Beşiktaş 100 m² aylık kira | C38: Konut | D38: 59200 | E38: Endeksa ortalaması | F38: Eylül 2026 | G38: Aylık | H38: https://www.gazetebirlik.com/ekonomi/istanbulda-ortalama-kira-57-bin-100-tl-oldu-en-pahali-ve-en-ucuz-ilceler-belli-oldu/1091377
A39: K03 | B39: Bakırköy 100 m² aylık kira | C39: Konut | D39: 59100 | E39: Endeksa ortalaması | F39: Eylül 2026 | G39: Aylık | H39: https://www.gazetebirlik.com/ekonomi/istanbulda-ortalama-kira-57-bin-100-tl-oldu-en-pahali-ve-en-ucuz-ilceler-belli-oldu/1091377
A40: K04 | B40: Esenyurt 100 m² aylık kira | C40: Konut | D40: 22800 | E40: Endeksa ortalaması | F40: Eylül 2026 | G40: Aylık | H40: https://www.gazetebirlik.com/ekonomi/istanbulda-ortalama-kira-57-bin-100-tl-oldu-en-pahali-ve-en-ucuz-ilceler-belli-oldu/1091377
...

Sheet Eşleşmeler
A1: A ürünü (ID) | B1: B ürünü (ID) | C1: A | D1: A fiyatı (TL) | E1: B | F1: B fiyatı (TL) | G1: Daha pahalı | H1: Fark %
A2: U06 | B2: D08 | C2: =IFERROR(INDEX(Ürünler!$B$2:$B$55,MATCH(A2,Ürünler!$A$2:$A$55,0)),"ID yok") -> YHT İstanbul–Ankara (tek yön, ekonomi) | D2: =IFERROR(INDEX(Ürünler!$D$2:$D$55,MATCH(A2,Ürünler!$A$2:$A$55,0)),0) -> 990 | E2: =IFERROR(INDEX(Ürünler!$B$2:$B$55,MATCH(B2,Ürünler!$A$2:$A$55,0)),"ID yok") -> 33 simit | F2: =IFERROR(INDEX(Ürünler!$D$2:$D$55,MATCH(B2,Ürünler!$A$2:$A$55,0)),0) -> 990 | G2: =IF(D2=F2,"Eşit",IF(D2>F2,C2,E2)) -> Eşit | H2: =IF(MIN(D2,F2)=0,0,ABS(D2-F2)/MIN(D2,F2)) -> 0
A3: U05 | B3: D07 | C3: =IFERROR(INDEX(Ürünler!$B$2:$B$55,MATCH(A3,Ürünler!$A$2:$A$55,0)),"ID yok") -> Taksi kısa mesafe ücreti (İstanbul) | D3: =IFERROR(INDEX(Ürünler!$D$2:$D$55,MATCH(A3,Ürünler!$A$2:$A$55,0)),0) -> 230 | E3: =IFERROR(INDEX(Ürünler!$B$2:$B$55,MATCH(B3,Ürünler!$A$2:$A$55,0)),"ID yok") -> 5 İstanbulkart tam biniş | F3: =IFERROR(INDEX(Ürünler!$D$2:$D$55,MATCH(B3,Ürünler!$A$2:$A$55,0)),0) -> 231 | G3: =IF(D3=F3,"Eşit",IF(D3>F3,C3,E3)) -> 5 İstanbulkart tam biniş | H3: =IF(MIN(D3,F3)=0,0,ABS(D3-F3)/MIN(D3,F3)) -> 0.0043478261
A4: D03 | B4: U07 | C4: =IFERROR(INDEX(Ürünler!$B$2:$B$55,MATCH(A4,Ürünler!$A$2:$A$55,0)),"ID yok") -> Spotify Bireysel 1 yıl | D4: =IFERROR(INDEX(Ürünler!$D$2:$D$55,MATCH(A4,Ürünler!$A$2:$A$55,0)),0) -> 1380 | E4: =IFERROR(INDEX(Ürünler!$B$2:$B$55,MATCH(B4,Ürünler!$A$2:$A$55,0)),"ID yok") -> YHT İstanbul–Konya (tek yön, ekonomi) | F4: =IFERROR(INDEX(Ürünler!$D$2:$D$55,MATCH(B4,Ürünler!$A$2:$A$55,0)),0) -> 1442 | G4: =IF(D4=F4,"Eşit",IF(D4>F4,C4,E4)) -> YHT İstanbul–Konya (tek yön, ekonomi) | H4: =IF(MIN(D4,F4)=0,0,ABS(D4-F4)/MIN(D4,F4)) -> 0.044927536
A5: T03 | B5: D05 | C5: =IFERROR(INDEX(Ürünler!$B$2:$B$55,MATCH(A5,Ürünler!$A$2:$A$55,0)),"ID yok") -> iPhone 18 Pro Max 2 TB | D5: =IFERROR(INDEX(Ürünler!$D$2:$D$55,MATCH(A5,Ürünler!$A$2:$A$55,0)),0) -> 255999 | E5: =IFERROR(INDEX(Ürünler!$B$2:$B$55,MATCH(B5,Ürünler!$A$2:$A$55,0)),"ID yok") -> Esenyurt 100 m² 1 yıllık kira | F5: =IFERROR(INDEX(Ürünler!$D$2:$D$55,MATCH(B5,Ürünler!$A$2:$A$55,0)),0) -> 273600 | G5: =IF(D5=F5,"Eşit",IF(D5>F5,C5,E5)) -> Esenyurt 100 m² 1 yıllık kira | H5: =IF(MIN(D5,F5)=0,0,ABS(D5-F5)/MIN(D5,F5)) -> 0.068754175
A6: D04 | B6: F03 | C6: =IFERROR(INDEX(Ürünler!$B$2:$B$55,MATCH(A6,Ürünler!$A$2:$A$55,0)),"ID yok") -> Mavi Kart 1 yıl | D6: =IFERROR(INDEX(Ürünler!$D$2:$D$55,MATCH(A6,Ürünler!$A$2:$A$55,0)),0) -> 43536 | E6: =IFERROR(INDEX(Ürünler!$B$2:$B$55,MATCH(B6,Ürünler!$A$2:$A$55,0)),"ID yok") -> Cumhuriyet altını | F6: =IFERROR(INDEX(Ürünler!$D$2:$D$55,MATCH(B6,Ürünler!$A$2:$A$55,0)),0) -> 42812 | G6: =IF(D6=F6,"Eşit",IF(D6>F6,C6,E6)) -> Mavi Kart 1 yıl | H6: =IF(MIN(D6,F6)=0,0,ABS(D6-F6)/MIN(D6,F6)) -> 0.016911146
A7: T01 | B7: D06 | C7: =IFERROR(INDEX(Ürünler!$B$2:$B$55,MATCH(A7,Ürünler!$A$2:$A$55,0)),"ID yok") -> iPhone 18 Pro 256 GB | D7: =IFERROR(INDEX(Ürünler!$D$2:$D$55,MATCH(A7,Ürünler!$A$2:$A$55,0)),0) -> 137999 | E7: =IFERROR(INDEX(Ürünler!$B$2:$B$55,MATCH(B7,Ürünler!$A$2:$A$55,0)),"ID yok") -> 5 aylık net asgari ücret | F7: =IFERROR(INDEX(Ürünler!$D$2:$D$55,MATCH(B7,Ürünler!$A$2:$A$55,0)),0) -> 140377.5 | G7: =IF(D7=F7,"Eşit",IF(D7>F7,C7,E7)) -> 5 aylık net asgari ücret | H7: =IF(MIN(D7,F7)=0,0,ABS(D7-F7)/MIN(D7,F7)) -> 0.017235632
A8: T07 | B8: K01 | C8: =IFERROR(INDEX(Ürünler!$B$2:$B$55,MATCH(A8,Ürünler!$A$2:$A$55,0)),"ID yok") -> PS5 Digital | D8: =IFERROR(INDEX(Ürünler!$D$2:$D$55,MATCH(A8,Ürünler!$A$2:$A$55,0)),0) -> 57999 | E8: =IFERROR(INDEX(Ürünler!$B$2:$B$55,MATCH(B8,Ürünler!$A$2:$A$55,0)),"ID yok") -> Kadıköy 100 m² aylık kira | F8: =IFERROR(INDEX(Ürünler!$D$2:$D$55,MATCH(B8,Ürünler!$A$2:$A$55,0)),0) -> 65100 | G8: =IF(D8=F8,"Eşit",IF(D8>F8,C8,E8)) -> Kadıköy 100 m² aylık kira | H8: =IF(MIN(D8,F8)=0,0,ABS(D8-F8)/MIN(D8,F8)) -> 0.12243315
A9: U03 | B9: D01 | C9: =IFERROR(INDEX(Ürünler!$B$2:$B$55,MATCH(A9,Ürünler!$A$2:$A$55,0)),"ID yok") -> Mavi Kart (aylık tam abonman) | D9: =IFERROR(INDEX(Ürünler!$D$2:$D$55,MATCH(A9,Ürünler!$A$2:$A$55,0)),0) -> 3628 | E9: =IFERROR(INDEX(Ürünler!$B$2:$B$55,MATCH(B9,Ürünler!$A$2:$A$55,0)),"ID yok") -> 50 litrelik benzin deposu | F9: =IFERROR(INDEX(Ürünler!$D$2:$D$55,MATCH(B9,Ürünler!$A$2:$A$55,0)),0) -> 4190 | G9: =IF(D9=F9,"Eşit",IF(D9>F9,C9,E9)) -> 50 litrelik benzin deposu | H9: =IF(MIN(D9,F9)=0,0,ABS(D9-F9)/MIN(D9,F9)) -> 0.15490628
A10: D02 | B10: F01 | C10: =IFERROR(INDEX(Ürünler!$B$2:$B$55,MATCH(A10,Ürünler!$A$2:$A$55,0)),"ID yok") -> Netflix Premium 1 yıl | D10: =IFERROR(INDEX(Ürünler!$D$2:$D$55,MATCH(A10,Ürünler!$A$2:$A$55,0)),0) -> 5999.88 | E10: =IFERROR(INDEX(Ürünler!$B$2:$B$55,MATCH(B10,Ürünler!$A$2:$A$55,0)),"ID yok") -> 1 gram altın | F10: =IFERROR(INDEX(Ürünler!$D$2:$D$55,MATCH(B10,Ürünler!$A$2:$A$55,0)),0) -> 6586.31 | G10: =IF(D10=F10,"Eşit",IF(D10>F10,C10,E10)) -> 1 gram altın | H10: =IF(MIN(D10,F10)=0,0,ABS(D10-F10)/MIN(D10,F10)) -> 0.097740288
A11: O02 | B11: O04 | C11: =IFERROR(INDEX(Ürünler!$B$2:$B$55,MATCH(A11,Ürünler!$A$2:$A$55,0)),"ID yok") -> Togg T10F (giriş) | D11: =IFERROR(INDEX(Ürünler!$D$2:$D$55,MATCH(A11,Ürünler!$A$2:$A$55,0)),0) -> 1884980 | E11: =IFERROR(INDEX(Ürünler!$B$2:$B$55,MATCH(B11,Ürünler!$A$2:$A$55,0)),"ID yok") -> Renault Duster (giriş) | F11: =IFERROR(INDEX(Ürünler!$D$2:$D$55,MATCH(B11,Ürünler!$A$2:$A$55,0)),0) -> 1865000 | G11: =IF(D11=F11,"Eşit",IF(D11>F11,C11,E11)) -> Togg T10F (giriş) | H11: =IF(MIN(D11,F11)=0,0,ABS(D11-F11)/MIN(D11,F11)) -> 0.010713137
A12: O03 | B12: O06 | C12: =IFERROR(INDEX(Ürünler!$B$2:$B$55,MATCH(A12,Ürünler!$A$2:$A$55,0)),"ID yok") -> Renault Clio evolution plus | D12: =IFERROR(INDEX(Ürünler!$D$2:$D$55,MATCH(A12,Ürünler!$A$2:$A$55,0)),0) -> 1830000 | E12: =IFERROR(INDEX(Ürünler!$B$2:$B$55,MATCH(B12,Ürünler!$A$2:$A$55,0)),"ID yok") -> Fiat Egea Cross (giriş, kampanyalı) | F12: =IFERROR(INDEX(Ürünler!$D$2:$D$55,MATCH(B12,Ürünler!$A$2:$A$55,0)),0) -> 1890900 | G12: =IF(D12=F12,"Eşit",IF(D12>F12,C12,E12)) -> Fiat Egea Cross (giriş, kampanyalı) | H12: =IF(MIN(D12,F12)=0,0,ABS(D12-F12)/MIN(D12,F12)) -> 0.033278689
A13: T04 | B13: D05 | C13: =IFERROR(INDEX(Ürünler!$B$2:$B$55,MATCH(A13,Ürünler!$A$2:$A$55,0)),"ID yok") -> iPhone Duo 256 GB (katlanabilir) | D13: =IFERROR(INDEX(Ürünler!$D$2:$D$55,MATCH(A13,Ürünler!$A$2:$A$55,0)),0) -> 229999 | E13: =IFERROR(INDEX(Ürünler!$B$2:$B$55,MATCH(B13,Ürünler!$A$2:$A$55,0)),"ID yok") -> Esenyurt 100 m² 1 yıllık kira | F13: =IFERROR(INDEX(Ürünler!$D$2:$D$55,MATCH(B13,Ürünler!$A$2:$A$55,0)),0) -> 273600 | G13: =IF(D13=F13,"Eşit",IF(D13>F13,C13,E13)) -> Esenyurt 100 m² 1 yıllık kira | H13: =IF(MIN(D13,F13)=0,0,ABS(D13-F13)/MIN(D13,F13)) -> 0.18957039
